<?xml version="1.0" ?>

<robot name="wheelchair">

  <mujoco>
        <compiler 
        meshdir="../meshes/" 
        discardvisual="false" />
  </mujoco>

  <gazebo>
    <plugin filename="libgazebo_ros_control.so" name="gazebo_ros_control">
      <robotNamespace>/</robotNamespace>
    </plugin>
  </gazebo>

    <link name="wam/wheelchair_link">
        <inertial>
        <origin rpy="0 0 0" xyz="0.0 0.0 0"/>
        <mass value="10"/>
        <inertia ixx="0.0001" ixy="0" ixz="0" iyy="0.0001" iyz="0" izz="0.0001"/>
        </inertial>
        <visual>
        <material name="WAMGrey">
            <color rgba="0.7 0.7 0.7 1.0"/>
        </material>
        <origin rpy="0 0 0" xyz="0 0 0"/>
        <geometry>
            <mesh filename="package://wam_model/models/sw_meshes/tennis_robot - base.stl" scale="1.5 1.5 1.5"/>
        </geometry>
        </visual>
        <collision>
        <origin rpy="0 0 0" xyz="0 0 0"/>
        <geometry>
            <mesh filename="package://wam_model/models/sw_meshes/tennis_robot - base.stl" scale="1.5 1.5 1.5"/>
        </geometry>
        </collision>
    </link>
    
    <joint name="frame_joint" type="fixed">
        <parent link="wam/wheelchair_link"/>
        <child link="frame"/>
        <origin rpy="0 0 0" xyz="0 0 0"/>
    </joint>

    <link name="frame">
    <visual>
      <origin rpy="0 0 0" xyz="0 0 0"/>
      <material name="WAMGrey">
        <color rgba="0.7 0.7 0.7 1.0"/>
      </material>
      <geometry>
        <mesh filename="package://wam_model/models/sw_meshes/tennis_robot - frame.stl" scale="1.5 1.5 1.5"/>
      </geometry>
    </visual>
    <collision>
      <origin rpy="0 0 0" xyz="0 0 0"/>
      <geometry>
        <mesh filename="package://wam_model/models/sw_meshes/tennis_robot - frame.stl" scale="1.5 1.5 1.5"/>
      </geometry>
    </collision>
  </link>

    <joint name="bracket_joint_1" type="revolute">
        <parent link="frame"/>
        <child link="bracket_1"/>
        <origin rpy="0 0 0" xyz="-0.25 -0.15  -0.47913650"/>
        <axis xyz="0 0 1"/>
        <limit effort="53" lower="-2.6" upper="2.6" velocity="10.0"/>
        <dynamics damping="0.9" friction="0"/>
    </joint>
    
    <joint name="bracket_joint_2" type="revolute">
        <parent link="frame"/>
        <child link="bracket_2"/>
        <origin rpy="0 0 0" xyz="-0.25 0.15  -0.47913650"/>
        <axis xyz="0 0 1"/>
        <limit effort="53" lower="-2.6" upper="2.6" velocity="10.0"/>
        <dynamics damping="0.9" friction="0"/>
    </joint>

    <joint name="bracket_joint_3" type="revolute">
        <parent link="frame"/>
        <child link="bracket_3"/>
        <origin rpy="0 0 0" xyz="0.33 0.00  -0.47913650"/>
        <axis xyz="0 0 1"/>
        <limit effort="53" lower="-2.6" upper="2.6" velocity="10.0"/>
        <dynamics damping="0.9" friction="0"/>
    </joint>


    <link name="bracket_3">
      <visual>
      <origin rpy="0 0 0" xyz="0 0 0"/>
      <material name="WAMGrey">
        <color rgba="0.7 0.7 0.7 1.0"/>
      </material>
      <geometry>
        <mesh filename="package://wam_model/models/sw_meshes/tennis_robot - bracket.stl" scale="1.5 1.5 1.5"/>
      </geometry>
    </visual>
    <collision>
      <origin rpy="0 0 0" xyz="0 0 0"/>
      <geometry>
        <mesh filename="package://wam_model/models/sw_meshes/tennis_robot - bracket.stl" scale="1.5 1.5 1.5"/>
      </geometry>
    </collision>
    </link>

  <link name="bracket_2">
      <visual>
      <origin rpy="0 0 0" xyz="0 0 0"/>
      <material name="WAMGrey">
        <color rgba="0.7 0.7 0.7 1.0"/>
      </material>
      <geometry>
        <mesh filename="package://wam_model/models/sw_meshes/tennis_robot - bracket.stl" scale="1.5 1.5 1.5"/>
      </geometry>
    </visual>
    <collision>
      <origin rpy="0 0 0" xyz="0 0 0"/>
      <geometry>
        <mesh filename="package://wam_model/models/sw_meshes/tennis_robot - bracket.stl" scale="1.5 1.5 1.5"/>
      </geometry>
    </collision>
  </link>


  <link name="bracket_1">
      <visual>
      <origin rpy="0 0 0" xyz="0 0 0"/>
      <material name="WAMGrey">
        <color rgba="0.7 0.7 0.7 1.0"/>
      </material>
      <geometry>
        <mesh filename="package://wam_model/models/sw_meshes/tennis_robot - bracket.stl" scale="1.5 1.5 1.5"/>
      </geometry>
    </visual>
    <collision>
      <origin rpy="0 0 0" xyz="0 0 0"/>
      <geometry>
        <mesh filename="package://wam_model/models/sw_meshes/tennis_robot - bracket.stl" scale="1.5 1.5 1.5"/>
      </geometry>
    </collision>
  </link>

    


    <joint name="wheel_joint_1" type="revolute">
        <parent link="frame"/>
        <child link="wheel_1"/>
        <origin rpy="1.06465 0 0" xyz="0.000  -0.45  -0.20"/>
        <axis xyz="0 0 1"/>
        <limit effort="53" lower="-2.6" upper="2.6" velocity="10.0"/>
        <dynamics damping="0.9" friction="0"/>
    </joint>

    <link name="wheel_1">
      <visual>
      <origin rpy="0 0 0" xyz="0 0 0"/>
      <material name="WAMGrey">
        <color rgba="0.7 0.7 0.7 1.0"/>
      </material>
      <geometry>
        <mesh filename="package://wam_model/models/sw_meshes/tennis_robot - Wheelchair Wheel.stl" scale="1.5 1.5 1.5"/>
      </geometry>
    </visual>
    <collision>
      <origin rpy="0 0 0" xyz="0 0 0"/>
      <geometry>
        <mesh filename="package://wam_model/models/sw_meshes/tennis_robot - Wheelchair Wheel.stl" scale="1.5 1.5 1.5"/>
      </geometry>
    </collision>
  </link>


    <joint name="wheel_joint_2" type="revolute">
        <parent link="frame"/>
        <child link="wheel_2"/>
        <origin rpy="-1.06465 0 0" xyz="0.000  0.45  -0.20"/>
        <axis xyz="0 0 1"/>
        <limit effort="53" lower="-2.6" upper="2.6" velocity="10.0"/>
        <dynamics damping="0.9" friction="0"/>
    </joint>

    <link name="wheel_2">
      <visual>
      <origin rpy="0 0 0" xyz="0 0 0"/>
      <material name="WAMGrey">
        <color rgba="0.7 0.7 0.7 1.0"/>
      </material>
      <geometry>
        <mesh filename="package://wam_model/models/sw_meshes/tennis_robot - Wheelchair Wheel.stl" scale="1.5 1.5 1.5"/>
      </geometry>
    </visual>
    <collision>
      <origin rpy="0 0 0" xyz="0 0 0"/>
      <geometry>
        <mesh filename="package://wam_model/models/sw_meshes/tennis_robot - Wheelchair Wheel.stl" scale="1.5 1.5 1.5"/>
      </geometry>
    </collision> 
  </link>

    <transmission name="wheel_1_trans">
        <type>transmission_interface/SimpleTransmission</type>
        <joint name="wheel_joint_1">
            <hardwareInterface>hardware_interface/PositionJointInterface</hardwareInterface>
        </joint>

        <actuator name="wheel_1_motor">
            <hardwareInterface>hardware_interface/PositionJointInterface</hardwareInterface>
            <mechanicalReduction>1</mechanicalReduction>
        </actuator>
    </transmission>

    <transmission name="wheel_2_trans">
        <type>transmission_interface/SimpleTransmission</type>
        <joint name="wheel_joint_2">
            <hardwareInterface>hardware_interface/PositionJointInterface</hardwareInterface>
        </joint>

        <actuator name="wheel_2_motor">
            <hardwareInterface>hardware_interface/PositionJointInterface</hardwareInterface>
            <mechanicalReduction>1</mechanicalReduction>
        </actuator>
    </transmission>



    <joint name="support_wheel_joint_1" type="revolute">
        <parent link="bracket_1"/>
        <child link="sw_1"/>
        <origin rpy="0 0 1.57" xyz="0 0 -0.037"/>
        <axis xyz="0 1 0"/>
        <limit effort="53" lower="-2.6" upper="2.6" velocity="10.0"/>
        <dynamics damping="0.9" friction="0"/>
    </joint>

    <link name="sw_1">
      <visual>
      <origin rpy="0 0 0" xyz="0 0 0"/>
      <material name="WAMGrey">
        <color rgba="0.7 0.7 0.7 1.0"/>
      </material>
      <geometry>
        <mesh filename="package://wam_model/models/sw_meshes/tennis_robot - whlsmall.stl" scale="1.5 1.5 1.5"/>
      </geometry>
    </visual>
    <collision>
      <origin rpy="0 0 0" xyz="0 0 0"/>
      <geometry>
        <mesh filename="package://wam_model/models/sw_meshes/tennis_robot - whlsmall.stl" scale="1.5 1.5 1.5"/>
      </geometry>
    </collision>
  </link>



    <joint name="support_wheel_joint_2" type="revolute">
        <parent link="bracket_2"/>
        <child link="sw_2"/>
        <origin rpy="0 0 1.57" xyz="0 0 -0.037"/>
        <axis xyz="0 1 0"/>
        <limit effort="53" lower="-2.6" upper="2.6" velocity="10.0"/>
        <dynamics damping="0.9" friction="0"/>

    </joint>

    <link name="sw_2">
      <visual>
      <origin rpy="0 0 0" xyz="0 0 0"/>
      <material name="WAMGrey">
        <color rgba="0.7 0.7 0.7 1.0"/>
      </material>
      <geometry>
        <mesh filename="package://wam_model/models/sw_meshes/tennis_robot - whlsmall.stl" scale="1.5 1.5 1.5"/>
      </geometry>
    </visual>
    <collision>
      <origin rpy="0 0 0" xyz="0 0 0"/>
      <geometry>
        <mesh filename="package://wam_model/models/sw_meshes/tennis_robot - whlsmall.stl" scale="1.5 1.5 1.5"/>
      </geometry>
    </collision>
  </link>

    <joint name="support_wheel_joint_3" type="revolute">
        <parent link="bracket_3"/>
        <child link="sw_3"/>
        <origin rpy="0 0 1.57" xyz="0 0 -0.037"/>
        <axis xyz="0 1 0"/>
        <limit effort="53" lower="-2.6" upper="2.6" velocity="10.0"/>
        <dynamics damping="0.9" friction="0"/>

    </joint>

    <link name="sw_3">
      <visual>
      <origin rpy="0 0 0" xyz="0 0 0"/>
      <material name="WAMGrey">
        <color rgba="0.7 0.7 0.7 1.0"/>
      </material>
      <geometry>
        <mesh filename="package://wam_model/models/sw_meshes/tennis_robot - whlsmall.stl" scale="1.5 1.5 1.5"/>
      </geometry>
    </visual>
    <collision>
      <origin rpy="0 0 0" xyz="0 0 0"/>
      <geometry>
        <mesh filename="package://wam_model/models/sw_meshes/tennis_robot - whlsmall.stl" scale="1.5 1.5 1.5"/>
      </geometry>
    </collision>
  </link>










  
    
</robot>