<?xml version="1.0" ?>
<!-- =================================================================================== -->
<!-- |    This document was autogenerated by xacro from /home/core-robotics/catkin_ws/src/Wheelchair-Tennis-Robot/wam_model/robots/wam7.urdf.xacro | -->
<!-- |    EDITING THIS FILE BY HAND IS NOT RECOMMENDED                                 | -->
<!-- =================================================================================== -->
<robot name="wam">
<!-- The convention of the coordinate system used here is similar to the one followed in 
     https://github.com/UW-Advanced-Robotics-Lab/uwarl-mujoco-summit-wam-sim/blob/main/components/include_wam_7dof_wam_bhand_Chain.xml

    pos: <z,x,y> + <0,0,0.346> 
    All units are in (m (pos),kg (mass),m**2 (MMI))
 -->

  <mujoco>
        <compiler 
        meshdir="../meshes/" 
        discardvisual="false"
        balanceinertia="true" />
  </mujoco>

  <gazebo>
    <plugin filename="libgazebo_ros_control.so" name="gazebo_ros_control">
      <robotNamespace>/</robotNamespace>
    </plugin>
  </gazebo>
  
  <material name="WAMGrey">
    <color rgba="0.7 0.7 0.7 1.0"/>
  </material>


  <!-- Root link is in the world frame-->


  <link name="world"/>
  <link name="base_link"/>

  <!-- <link name="wall"/> -->


<!-- Start of Wall definition -->
  <joint name="wall_joint" type="fixed">
    <parent link="world"/>
    <child link="wall"/>
    <origin rpy="0 0 1.57" xyz="15.885 0.0 2"/>
    <!-- <origin rpy="0 0 0" xyz="1 1 1"/> -->
  </joint>
    <link name="wall">
    <inertial>
      <!-- <origin xyz="-0.02 -0.1407 0.266"/> -->
      <origin xyz="-0.02 0.266 -0.147"/>
      <mass value="1000"/>

      <!-- <inertia ixx="0.10916849" ixy="0.02557874" ixz="-0.00640270" iyy="0.11760385" iyz="-0.00161433" izz="0.18294303"/> -->
    <inertia ixx="0.10916849" ixy="0.00640270" ixz="0.02557874" iyy="0.18294303" iyz="-0.00161433" izz="0.11760385"/>
    </inertial>
    <visual>
      <material name="WAMGrey">
        <color rgba="1 0.7 0.7 1"/>
      </material>
      <geometry>
        <mesh filename="package://wam_model/models/sw_meshes/Assembly 1 - Wall.stl"/>
      </geometry>
    </visual>
    <collision>
      <geometry>
        <mesh filename="package://wam_model/models/sw_meshes/Assembly 1 - Wall.stl"/>
      </geometry>
    </collision>
  </link>
<!-- End of wall definition -->



<!-- Start of ball defintion-->
    <joint name="ball_joint" type="floating">
    <parent link="wall"/>
    <child link="ball"/>
    <origin rpy="0 0 1.57" xyz="12.2 0.0 4"/>
    <!-- <origin rpy="0 0 0" xyz="1 1 1"/> -->
  </joint>

  <link name="ball">
    <inertial>
      <!-- <origin xyz="-0.02 -0.1407 0.266"/> -->
      <origin xyz="1 0.266 -0.147"/>
      <mass value="0.056"/>

      <!-- <inertia ixx="0.10916849" ixy="0.02557874" ixz="-0.00640270" iyy="0.11760385" iyz="-0.00161433" izz="0.18294303"/> -->
    <inertia ixx="0.10916849" ixy="0.00640270" ixz="0.02557874" iyy="0.18294303" iyz="-0.00161433" izz="0.11760385"/>
    </inertial>
    <visual>
      <material name="WAMGrey">
        <color rgba="0 1 0.6 1"/>
      </material>
      <geometry>
        <sphere radius="0.1"/>
      </geometry>
    </visual>
    <collision>
      <geometry>
        <sphere radius="0.1"/>
      </geometry>
    </collision>
  </link>
<!-- End of Ball definition -->





<!-- Start of WTR URDF -->

  <joint name="base_link_joint" type="floating">
    <parent link="world"/>
    <child link="base_link"/>
    <origin rpy="0 0 0" xyz="0 0 0"/>
  </joint>

  <joint name="wam/wam_fixed_joint" type="fixed">
    <parent link="base_link"/>
    <child link="wam/base_link"/>
    <!-- <origin rpy="0 0 3.141592653589793" xyz=".0793752 0.0 0.001"/> -->
    <origin rpy="0 0 0" xyz="0.02 0.0 0.001"/>
  </joint> 

  <gazebo reference="wam/base_link">
    <material>Gazebo/Grey</material>
  </gazebo>

  <link name="wam/base_link">
    <inertial>
      <!-- <origin xyz="-0.02 -0.1407 0.266"/> -->
      <origin xyz="-0.02 0.266 -0.147"/>
      <mass value="9.97"/>

      <!-- <inertia ixx="0.10916849" ixy="0.02557874" ixz="-0.00640270" iyy="0.11760385" iyz="-0.00161433" izz="0.18294303"/> -->
    <inertia ixx="0.10916849" ixy="0.00640270" ixz="0.02557874" iyy="0.18294303" iyz="-0.00161433" izz="0.11760385"/>
    </inertial>
    <visual>
      <material name="WAMGrey">
        <color rgba="0.7 0.7 0.7 1"/>
      </material>
      <geometry>
        <mesh filename="package://wam_model/models/sw_meshes/base_link_fine.stl" scale="1.5 1.3 1.3"/>
      </geometry>
    </visual>
    <collision>
      <geometry>
        <mesh filename="package://wam_model/models/sw_meshes/base_link_fine.stl" scale="1.5 1.3 1.3"/>
      </geometry>
    </collision>
  </link>

  <joint name="wam/base_yaw_joint" type="revolute">
    <parent link="wam/base_link"/>
    <child link="wam/shoulder_yaw_link"/>
    <origin rpy="0 0 0" xyz="0 0 0.446"/>
    <axis xyz="0 0 1"/>
    <limit effort="53" lower="-2.6" upper="2.6" velocity="3.9"/>
    <dynamics damping="5.5" friction="0.3"/>
  </joint>

  <!-- <gazebo reference="wam/base_yaw_joint">
    <provideFeedback>true</provideFeedback>
    <implicitSpringDamper>true</implicitSpringDamper>
    <kp>0.0</kp> [> CFM <]
    <kd>0.0</kd>[> ERP <]
    <cfmDamping>true</cfmDamping>
    <dynamics damping="5.5" friction="1"/>
  </gazebo> -->

  <transmission name="wam/base_yaw_trans">
    <type>transmission_interface/SimpleTransmission</type>
    <joint name="wam/base_yaw_joint">
      <hardwareInterface>hardware_interface/PositionJointInterface</hardwareInterface>
    </joint>
    <actuator name="wam/base_yaw_motor">
      <hardwareInterface>hardware_interface/PositionJointInterface</hardwareInterface>
      <motorInertia>0.205190</motorInertia>
      <mechanicalReduction>42</mechanicalReduction>
    </actuator>
  </transmission>

  <gazebo reference="wam/shoulder_yaw_link">
    <material>Gazebo/Grey</material>
  </gazebo>
  <link name="wam/shoulder_yaw_link">
    <inertial>
      <!-- <origin xyz="-.00443422 -.00066489 -0.1289039 "/> -->
      <origin xyz="-.00443422 0.1289039 -0.00066489"/>
      <mass value="10.77"/>
      <!-- <inertia ixx=".13488033" ixy="-0.00012485" ixz="0.00213041" iyy=".09046330" iyz="-.00068555" izz=".11328369"/> -->
      <inertia ixx=".13488033" ixy="-0.00213041" ixz="-0.00012485" iyy="0.11328369" iyz="0.00068555" izz="0.09046330"/>
    </inertial>
    <visual>
      <material name="WAMGrey">
        <color rgba="0.7 0.7 0.7 1.0"/>
      </material>
      <geometry>
        <mesh filename="package://wam_model/models/sw_meshes/shoulder_link_fine.stl" scale="1.3 1.3 1.3"/>
      </geometry>
    </visual>
    <collision>
      <geometry>
        <mesh filename="package://wam_model/models/sw_meshes/shoulder_link_fine.stl" scale="1.3 1.3 1.3"/>
      </geometry>
    </collision>
  </link>

  <joint name="wam/shoulder_pitch_joint" type="revolute">
    <parent link="wam/shoulder_yaw_link"/>
    <child link="wam/shoulder_pitch_link"/>
    <origin rpy="-1.5707963267948966 0 0" xyz="0 0 0"/>
    <axis xyz="0 0 1"/>
    <limit effort="53" lower="-1.98" upper="1.98" velocity="6.3"/>
    <dynamics damping="5.5" friction="0.3"/>
  </joint>
  <!-- <gazebo reference="wam/shoulder_pitch_joint">
    <provideFeedback>true</provideFeedback>
    <implicitSpringDamper>true</implicitSpringDamper>
    <kp>0.0</kp>[> CFM <]
    <kd>0.0</kd>[> ERP <]
    <cfmDamping>true</cfmDamping>
    <dynamics damping="5.5" friction="1"/>
  </gazebo> -->
  <transmission name="wam/shoulder_pitch_trans">
    <type>transmission_interface/SimpleTransmission</type>
    <joint name="wam/shoulder_pitch_joint">
      <hardwareInterface>hardware_interface/PositionJointInterface</hardwareInterface>
    </joint>
    <actuator name="wam/shoulder_pitch_motor">
      <hardwareInterface>hardware_interface/PositionJointInterface</hardwareInterface>
      <motorInertia>0.094428</motorInertia>
      <mechanicalReduction>28.25</mechanicalReduction>
    </actuator>
  </transmission>
  <gazebo reference="wam/shoulder_pitch_link">
    <material>Gazebo/Grey</material>
  </gazebo>

  <link name="wam/shoulder_pitch_link">
    <visual>
      <material name="WAMGrey">
        <color rgba="0.7 0.7 0.7 1.0"/>
      </material>
      <geometry>
        <mesh filename="package://wam_model/models/sw_meshes/shoulder_pitch_link_fine.stl" scale="1.3 1.3 1.3"/>
      </geometry>
    </visual>
    <inertial>
      <!-- <origin xyz="-.00236981 -.01542114 .03105614 "/> -->
      <origin xyz="-.00236981 0.03105614 -0.01542114"/>
      <mass value="3.87"/>
      <!-- <inertia ixx="0.02140958" ixy="0.00002461" ixz="-0.00027172" iyy="0.015589060" iyz="0.0018192" izz="0.01377875"/> -->
      <inertia ixx="0.02140958" ixy="0.00027172" ixz="0.00002461" iyy="0.01377875" iyz="-0.00181920" izz="0.01558906"/>
    </inertial>
    <collision>
      <geometry>
        <mesh filename="package://wam_model/models/sw_meshes/shoulder_pitch_link_convex.stl" scale="1.3 1.3 1.3"/>
      </geometry>
    </collision>
  </link>

  <joint name="wam/shoulder_yaw_joint" type="revolute">
    <parent link="wam/shoulder_pitch_link"/>
    <child link="wam/upper_arm_link"/>
    <origin rpy="1.5707963267948966 0 0" xyz="0 0 0"/>
    <axis xyz="0 0 1"/>
    <limit effort="45" lower="-2.8" upper="2.8" velocity="10"/>
    <dynamics damping="5.5" friction="0.3"/>
  </joint>
  <!-- <gazebo reference="wam/shoulder_yaw_joint">
    <provideFeedback>true</provideFeedback>
    <implicitSpringDamper>true</implicitSpringDamper>
    <kp>0.0</kp>[> CFM <]
    <kd>0.0</kd>[> ERP <]
    <cfmDamping>true</cfmDamping>
    <dynamics damping="5.5" friction="1"/>
  </gazebo> -->
  <transmission name="wam/shoulder_yaw_trans">
    <type>transmission_interface/SimpleTransmission</type>
    <joint name="wam/shoulder_yaw_joint">
      <hardwareInterface>hardware_interface/PositionJointInterface</hardwareInterface>
    </joint>
    <actuator name="wam/shoulder_yaw_motor">
      <hardwareInterface>hardware_interface/PositionJointInterface</hardwareInterface>
      <motorInertia>0.094428</motorInertia>
      <mechanicalReduction>28.25</mechanicalReduction>
    </actuator>
  </transmission>
  <gazebo reference="wam/upper_arm_link">
    <material>Gazebo/Grey</material>
  </gazebo>
  
  <link name="wam/upper_arm_link">
    <inertial>
      <!-- <origin xyz="-0.03825858  0.000033090000000 -0.20750770"/> -->
      <origin xyz="-0.03825858 0.20750770 0.000033090000000"/>
      <mass value="1.8"/>
      <!-- <inertia ixx="0.05911077" ixy="0.00000738" ixz="0.00249612" iyy="0.05927043" iyz="0.00001767" izz="0.0032455"/> -->
      <inertia ixx="0.05911077" ixy="-0.00249612" ixz="0.00000738" iyy="0.00324550" iyz="-0.00001767" izz="0.05927043"/>
    </inertial>
    <visual>
      <material name="WAMGrey">
        <color rgba="0.7 0.7 0.7 1.0"/>
      </material>
      <geometry>
        <mesh filename="package://wam_model/models/sw_meshes/upper_arm_link_fine.stl" scale="1.3 1.3 1.3"/>
      </geometry>
    </visual>
    <collision>
      <geometry>
        <mesh filename="package://wam_model/models/sw_meshes/upper_arm_link_fine.stl" scale="1.3 1.3 1.3"/>
      </geometry>
    </collision>
  </link>

  <joint name="wam/elbow_pitch_joint" type="revolute">
    <parent link="wam/upper_arm_link"/>
    <child link="wam/forearm_link"/>
    <origin rpy="-1.5707963267948966 0 0" xyz="0.045 0 0.73"/>
    <axis xyz="0 0 1"/>
    <limit effort="30" lower="-0.9" upper="3.1" velocity="10"/>
    <dynamics damping="5.5" friction="0.3"/>
  </joint>
  <!-- <gazebo reference="wam/elbow_pitch_joint">
    <provideFeedback>true</provideFeedback>
    <implicitSpringDamper>true</implicitSpringDamper>
    <kp>0.0</kp>[> CFM <]
    <kd>0.0</kd>[> ERP <]
    <cfmDamping>true</cfmDamping>
    <dynamics damping="5.5" friction="1"/>
  </gazebo> -->
  <transmission name="wam/elbow_pitch_trans">
    <type>transmission_interface/SimpleTransmission</type>
    <joint name="wam/elbow_pitch_joint">
      <hardwareInterface>hardware_interface/PositionJointInterface</hardwareInterface>
    </joint>
    <actuator name="wam/elbow_pitch_motor">
      <hardwareInterface>hardware_interface/PositionJointInterface</hardwareInterface>
      <motorInertia>0.034628</motorInertia>
      <mechanicalReduction>18</mechanicalReduction>
    </actuator>
  </transmission>
  <gazebo reference="wam/forearm_link">
    <material>Gazebo/Grey</material>
  </gazebo>
  <link name="wam/forearm_link">
    <inertial>
      <mass value="2.4"/>
      <!-- <origin rpy="0 0 0" xyz="0.00498512 0.13271662 0.00022942"/> -->
      <origin rpy="0 0 0" xyz="0.00498512 -0.00022942 0.13271662"/>
      <!-- <inertia ixx="0.01491672" ixy="-0.001506040000000" ixz="-0.000017410000000" iyy="0.002944630000000" iyz="0.000021090000000" izz="0.014829880000000"/> -->
      <inertia ixx="0.01491672" ixy="0.00001741" ixz="-0.00150604" iyy="0.01482922" iyz="-0.00002109" izz="0.00294463"/>
    </inertial>
    <visual>
      <material name="WAMGrey">
        <color rgba="0.7 0.7 0.7 1.0"/>
      </material>
      <geometry>
        <mesh filename="package://wam_model/models/sw_meshes/elbow_link_fine.stl" scale="1.3 1.3 1.3"/>
      </geometry>
    </visual>
    <collision>
      <geometry>
        <mesh filename="package://wam_model/models/sw_meshes/elbow_link_convex.stl" scale="1.3 1.3 1.3"/>
      </geometry>
    </collision>
    <visual>
      <material name="WAMGrey">
        <color rgba="0.7 0.7 0.7 1.0"/>
      </material>
      <origin rpy="1.5707963267948966 0 0" xyz="-0.045 -0.0730 0"/>
      <geometry>
        <mesh filename="package://wam_model/models/sw_meshes/forearm_link_fine.stl"/>
      </geometry>
    </visual>
    <collision>
      <origin rpy="1.5707963267948966 0 0" xyz="-0.045 -0.0730 0"/>
      <geometry>
        <mesh filename="package://wam_model/models/sw_meshes/forearm_link_convex_decomposition.stl"/>
      </geometry>
    </collision>
  </link>
  <joint name="wam/wrist_yaw_joint" type="revolute">
    <parent link="wam/forearm_link"/>
    <child link="wam/wrist_yaw_link"/>
    <origin rpy="1.5707963267948966 3.141592653589793 0" xyz="-0.045 -0.3 0"/>
    <axis xyz="0 0 1"/>
    <limit effort="10" lower="-4.65" upper="1.35" velocity="24"/>
    <dynamics damping="5.5" friction="0.3"/>
  </joint>
  <!-- <gazebo reference="wam/wrist_yaw_joint">
    <provideFeedback>true</provideFeedback>
    <implicitSpringDamper>true</implicitSpringDamper>
    <kp>0.0</kp>[> CFM <]
    <kd>0.0</kd>[> ERP <]
    <cfmDamping>true</cfmDamping>
    <dynamics damping="5.5" friction="1"/>
  </gazebo> -->
  <transmission name="wam/wrist_yaw_trans">
    <type>transmission_interface/SimpleTransmission</type>
    <joint name="wam/wrist_yaw_joint">
      <hardwareInterface>hardware_interface/PositionJointInterface</hardwareInterface>
    </joint>
    <actuator name="wam/wrist_yaw_motor">
      <hardwareInterface>hardware_interface/PositionJointInterface</hardwareInterface>
      <motorInertia>0.001584</motorInertia>
      <mechanicalReduction>9.48</mechanicalReduction>
    </actuator>
  </transmission>
  <gazebo reference="wam/wrist_yaw_link">
    <material>Gazebo/Grey</material>
  </gazebo>
  <link name="wam/wrist_yaw_link">
    <inertial>
      <!-- <origin xyz="0.00008921 0.00435824 -0.00511217 "/> -->
      <origin xyz="0.00008921 0.00511217 0.00435824"/>
      <mass value="0.124"/>
      <!-- <inertia ixx="0.00005029" ixy="0.00000005" ixz="-0.00000020" iyy="0.00006270" iyz="0.00000359" izz="0.00007582"/> -->
      <inertia ixx="0.00005029" ixy="0.00000020" ixz="-0.00000005" iyy="0.00007582" iyz="-0.00000359" izz="0.00006270"/>
      <!-- <inertia ixx="0.1" ixy="0" ixz="0" iyy="0.1" iyz="0" izz="0.1"/> -->

    </inertial>
    <visual>
      <material name="WAMGrey">
        <color rgba="0.7 0.7 0.7 1.0"/>
      </material>
      <origin rpy="0 0 0" xyz="0 0 0"/>
      <geometry>
        <mesh filename="package://wam_model/models/sw_meshes/wrist_yaw_link_fine.stl" scale="1.3 1.3 1.3"/>
      </geometry>
    </visual>
    <collision>
      <origin rpy="0 0 0" xyz="0 0 0"/>
      <geometry>
        <mesh filename="package://wam_model/models/sw_meshes/wrist_yaw_link_convex_decomposition.stl" scale="1.3 1.3 1.3"/>
      </geometry>
    </collision>
  </link>
  <joint name="wam/wrist_pitch_joint" type="revolute">
    <parent link="wam/wrist_yaw_link"/>
    <child link="wam/wrist_pitch_link"/>
    <origin rpy="-1.5707963267948966 0 3.141592653589793" xyz="0 0 0"/>
    <axis xyz="0 0 1"/>
    <limit effort="10" lower="-1.5707" upper="1.5707" velocity="19"/>
    <dynamics damping="5.5" friction="0.3"/>
  </joint>
  <!-- <gazebo reference="wam/wrist_pitch_joint">
    <provideFeedback>true</provideFeedback>
    <implicitSpringDamper>true</implicitSpringDamper>
    <kp>0.0</kp>[> CFM <]
    <kd>0.0</kd>[> ERP <]
    <cfmDamping>true</cfmDamping>
    <dynamics damping="5.5" friction="1"/>
  </gazebo> -->
  <transmission name="wam/wrist_pitch_trans">
    <type>transmission_interface/SimpleTransmission</type>
    <joint name="wam/wrist_pitch_joint">
      <hardwareInterface>hardware_interface/PositionJointInterface</hardwareInterface>
    </joint>
    <actuator name="wam/wrist_pitch_motor">
      <hardwareInterface>hardware_interface/PositionJointInterface</hardwareInterface>
      <motorInertia>0.00001745</motorInertia>
      <mechanicalReduction>9.48</mechanicalReduction>
    </actuator>
  </transmission>
  <gazebo reference="wam/wrist_pitch_link">
    <material>Gazebo/Grey</material>
  </gazebo>
  <link name="wam/wrist_pitch_link">
    <inertial>
      <!-- <origin rpy="0 0 0" xyz="-0.00012262 0.02468336 0.01703194 "/> -->
      <origin rpy="0 0 0" xyz="-0.00012262 -0.01703194 0.02468336"/>
      <mass value="0.4179"/>
      <!-- <inertia ixx="0.00055516" ixz="-0.00000061" ixy="-0.00000074" iyy="0.00045358" iyz="0.00004590" izz="0.00024367"/> -->
      <inertia ixx="0.00055516" ixz="0.00000061" ixy="-0.00000074" iyy="0.00024367" iyz="-0.00004590" izz="0.00045358"/>
    </inertial>
    <visual>
      <material name="WAMGrey">
        <color rgba="0.7 0.7 0.7 1.0"/>
      </material>
      <geometry>
        <mesh filename="package://wam_model/models/sw_meshes/wrist_pitch_link_fine.stl" scale="1.3 1.3 1.3"/>
      </geometry>
    </visual>
    <collision>
      <geometry>
        <mesh filename="package://wam_model/models/sw_meshes/wrist_pitch_link_convex_decomposition.stl" scale="1.3 1.3 1.3"/>
      </geometry>
    </collision>
  </link>
  <joint name="wam/palm_yaw_joint" type="revolute">
    <parent link="wam/wrist_pitch_link"/>
    <child link="wam/wrist_palm_link"/>
    <origin rpy="1.5707963267948966 0 0" xyz="0 0 0"/>
    <axis xyz="0 0 1"/>
    <limit effort="10" lower="-2.95" upper="2.95" velocity="27"/>
    <dynamics damping="5.5" friction="0.3"/>
  </joint>
  <!-- <gazebo reference="wam/palm_yaw_joint">
    <provideFeedback>true</provideFeedback>
    <implicitSpringDamper>true</implicitSpringDamper>
    <kp>0.0</kp>[> CFM <]
    <kd>0.0</kd>[> ERP <]
    <cfmDamping>true</cfmDamping>
    <dynamics damping="5.5" friction="1"/>
  </gazebo> -->
  <transmission name="wam/palm_yaw_trans">
    <type>transmission_interface/SimpleTransmission</type>
    <joint name="wam/palm_yaw_joint">
      <hardwareInterface>hardware_interface/PositionJointInterface</hardwareInterface>
    </joint>
    <actuator name="wam/palm_yaw_motor">
      <hardwareInterface>hardware_interface/PositionJointInterface</hardwareInterface>
      <motorInertia>0.000318</motorInertia>
      <mechanicalReduction>14.93</mechanicalReduction>
    </actuator>
  </transmission>
  <gazebo reference="wam/wrist_palm_link">
    <material>Gazebo/Grey</material>
  </gazebo>
  <link name="wam/wrist_palm_link">
    <inertial>
      <origin rpy="0 0 0" xyz="0.0 0.0 0.055"/>
      <mass value="0.001"/>
      <inertia ixx="0.00010859" ixy="0.00000000" ixz="-0.00000000" iyy="0.00020683" iyz="-0.0000000" izz="0.00010851"/>
    </inertial>
    <visual>
      <material name="WAMGrey">
        <color rgba="0.7 0.7 0.7 1.0"/>
      </material>
      <origin rpy="0 0 0" xyz="0 0 0"/>
      <geometry>
        <mesh filename="package://wam_model/models/sw_meshes/wrist_palm_link_fine.stl" scale="1.3 1.3 1.3"/>
      </geometry>
    </visual>
    <collision>
      <origin rpy="0 0 0" xyz="0 0 0"/>
      <geometry>
        <mesh filename="package://wam_model/models/sw_meshes/wrist_palm_link_convex.stl" scale="1.3 1.3 1.3"/>
      </geometry>
    </collision>
  </link>
  <joint name="wam/wrist_palm_stump_joint" type="fixed">
    <parent link="wam/wrist_palm_link"/>
    <child link="wam/wrist_palm_stump_link"/>
    <origin rpy="0 0 0" xyz="0 0 0.06"/>
  </joint>
  <link name="wam/wrist_palm_stump_link">
    <inertial>
      <mass value="0.001"/>
      <inertia ixx="0.0000001" ixy="0.0" ixz="0.0" iyy="0.0000001" iyz="0.0" izz="0.0000001"/>
    </inertial>
  </link>
  <joint name="wam/racquet_joint" type="fixed">
    <parent link="wam/wrist_palm_stump_link"/>
    <child link="wam/racquet_link"/>
    <!-- for racket head in straight position -->
    <!-- <origin xyz="0 0 0.01" rpy="0 0 0"/> -->
    <!-- for racket head in perpendicular starting position -->
    <origin rpy="0 1.57 0" xyz="0 0 0.60"/>
  </joint>
  <gazebo reference="wam/racquet_link">
    <material>Gazebo/Grey</material>
  </gazebo>
  <link name="wam/racquet_link">
    <inertial>
      <mass value="0.1"/>
      <inertia ixx="0.0001" ixy="0" ixz="0" iyy="0.0001" iyz="0" izz="0.0001"/>
    </inertial>
    <visual>
      <material name="WAMGrey">
        <color rgba="0.7 0.7 0.7 1.0"/>
      </material>
      <origin rpy="0 0 0" xyz="0 0 0"/>
      <geometry>
        <mesh filename="package://wam_model/models/sw_meshes/tennis_robot - racquet.stl" scale="1.2 1.2 1.2"/>
      </geometry>
    </visual>
    <collision>
      <origin rpy="0 0 0" xyz="0 0 0"/>
      <geometry>
        <mesh filename="package://wam_model/models/sw_meshes/tennis_robot - racquet.stl" scale="1.2 1.2 1.2"/>
      </geometry>
    </collision>
  </link>
  <link name="wam/racquet_hitpoint_link"/>
  <joint name="wam/racquet_hitpoint_joint" type="fixed">
    <parent link="wam/racquet_link"/>
    <child link="wam/racquet_hitpoint_link"/>
    <origin rpy="0 1.5707963267948966 0" xyz="0 0 0.520"/>
  </joint>
  <joint name="wam/wheelchair_joint" type="fixed">
    <parent link="base_link"/>
    <child link="wam/wheelchair_link"/>
    <origin rpy="0 0 0" xyz="0 0 0"/>
  </joint>
  


<!-- New Wheel chair tags added based on the STL files obtained-->
<!-- Start -->
 <link name="wam/wheelchair_link">
    <inertial>
    <origin rpy="0 0 0" xyz="0.0 0.0 0"/>
    <mass value="10"/>
    <inertia ixx=".13488033" ixy="-0.00213041" ixz="-0.00012485" iyy="0.11328369" iyz="0.00068555" izz="0.09046330"/>
    </inertial>
    <visual>
    <material name="WAMGrey">
        <color rgba="0.7 0.7 0.7 1.0"/>
    </material>
    <origin rpy="0 0 0" xyz="0 0 0"/>
    <geometry>
        <mesh filename="package://wam_model/models/sw_meshes/tennis_robot - base.stl" scale="1.5 1.5 1.5"/>
    </geometry>
    </visual>
    <collision>
    <origin rpy="0 0 0" xyz="0 0 0"/>
    <geometry>
        <mesh filename="package://wam_model/models/sw_meshes/tennis_robot - base.stl" scale="1.5 1.5 1.5"/>
    </geometry>
    </collision>
    </link>
    
    <joint name="frame_joint" type="fixed">
        <parent link="wam/wheelchair_link"/>
        <child link="frame"/>
        <origin rpy="0 0 0" xyz="0 0 0"/>
    </joint>

    <link name="frame">
    <inertial>
    <origin rpy="0 0 0" xyz="0.0 0.0 0"/>
    <mass value="10"/>
    <inertia ixx=".13488033" ixy="-0.00213041" ixz="-0.00012485" iyy="0.11328369" iyz="0.00068555" izz="0.09046330"/>
    </inertial>
    <visual>
      <origin rpy="0 0 0" xyz="0 0 0"/>
      <material name="WAMGrey">
        <color rgba="0.7 0.7 0.7 1.0"/>
      </material>
      <geometry>
        <mesh filename="package://wam_model/models/sw_meshes/tennis_robot - frame.stl" scale="1.5 1.5 1.5"/>
      </geometry>
    </visual>
    <collision>
      <origin rpy="0 0 0" xyz="0 0 0"/>
      <geometry>
        <mesh filename="package://wam_model/models/sw_meshes/tennis_robot - frame.stl" scale="1.5 1.5 1.5"/>
      </geometry>
    </collision>
  </link>

    <joint name="bracket_joint_1" type="revolute">
        <parent link="frame"/>
        <child link="bracket_1"/>
        <origin rpy="0 0 1.57" xyz="-0.25 -0.15  -0.49513650"/>
        <axis xyz="0 0 1"/>
        <limit effort="53" velocity="3"/>
        <dynamics damping="0.9" friction="0"/>
    </joint>
    
    <joint name="bracket_joint_2" type="revolute">
        <parent link="frame"/>
        <child link="bracket_2"/>
        <origin rpy="0 0 1.57" xyz="-0.25 0.15  -0.49513650"/>
        <axis xyz="0 0 1"/>
        <limit effort="53" velocity="3"/>
        <dynamics damping="0.9" friction="0"/>
    </joint>

    <joint name="bracket_joint_3" type="revolute">
        <parent link="frame"/>
        <child link="bracket_3"/>
        <origin rpy="0 0 1.57" xyz="0.33 0.00  -0.49513650"/>
        <axis xyz="0 0 1"/>
        <limit effort="53" velocity="3"/>
        <dynamics damping="0.9" friction="0"/>
    </joint>


    <link name="bracket_3">
     <inertial>
    <mass value="0.67"/>
    <inertia ixx="0.01" ixy="0" ixz="0" iyy="0.01" iyz="0" izz="0.01"/>
    </inertial>
      <visual>
      <origin rpy="0 0 0" xyz="0 0 0"/>
      <material name="WAMGrey">
        <color rgba="0.7 0.7 0.7 1.0"/>
      </material>
      <geometry>
        <mesh filename="package://wam_model/models/sw_meshes/tennis_robot - bracket.stl" scale="1.5 1.5 1.5"/>
      </geometry>
    </visual>
    <collision>
      <origin rpy="0 0 0" xyz="0 0 0"/>
      <geometry>
        <mesh filename="package://wam_model/models/sw_meshes/tennis_robot - bracket.stl" scale="1.5 1.5 1.5"/>
      </geometry>
    </collision>
    </link>

  <link name="bracket_2">
   <inertial>
    <mass value="0.67"/>
    <inertia ixx="0.01" ixy="0" ixz="0" iyy="0.01" iyz="0" izz="0.01"/>
    </inertial>
      <visual>
      <origin rpy="0 0 0" xyz="0 0 0"/>
      <material name="WAMGrey">
        <color rgba="0.7 0.7 0.7 1.0"/>
      </material>
      <geometry>
        <mesh filename="package://wam_model/models/sw_meshes/tennis_robot - bracket.stl" scale="1.5 1.5 1.5"/>
      </geometry>
    </visual>
    <collision>
      <origin rpy="0 0 0" xyz="0 0 0"/>
      <geometry>
        <mesh filename="package://wam_model/models/sw_meshes/tennis_robot - bracket.stl" scale="1.5 1.5 1.5"/>
      </geometry>
    </collision>
  </link>


  <link name="bracket_1">
   <inertial>
    <mass value="0.67"/>
    <inertia ixx="0.01" ixy="0" ixz="0" iyy="0.01" iyz="0" izz="0.01"/>
    </inertial>
      <visual>
      <origin rpy="0 0 0" xyz="0 0 0"/>
      <material name="WAMGrey">
        <color rgba="0.7 0.7 0.7 1.0"/>
      </material>
      <geometry>
        <mesh filename="package://wam_model/models/sw_meshes/tennis_robot - bracket.stl" scale="1.5 1.5 1.5"/>
      </geometry>
    </visual>
    <collision>
      <origin rpy="0 0 0" xyz="0 0 0"/>
      <geometry>
        <mesh filename="package://wam_model/models/sw_meshes/tennis_robot - bracket.stl" scale="1.5 1.5 1.5"/>
      </geometry>
    </collision>
  </link>

    
    <joint name="wheel_joint_1" type="revolute">
        <parent link="frame"/>
        <child link="wheel_1"/>
        <origin rpy="1.06465 0 0" xyz="0.000  -0.45  -0.20"/>
        <axis xyz="0 0 1"/>
        <limit effort="53"  velocity="3"/>
        <dynamics damping="0.9" friction="0"/>
    </joint>

    <link name="wheel_1">
    <inertial>
    <origin rpy="0 0 0" xyz="0.0 0.0 0"/>
    <mass value="0.5"/>
    <inertia ixx=".13488033" ixy="-0.00213041" ixz="-0.00012485" iyy="0.11328369" iyz="0.00068555" izz="0.09046330"/>
    </inertial>
      <visual>
      <origin rpy="0 0 0" xyz="0 0 0"/>
      <material name="WAMGrey">
        <color rgba="0.7 0.7 0.7 1.0"/>
      </material>
      <geometry>
        <mesh filename="package://wam_model/models/sw_meshes/tennis_robot - Wheelchair Wheel.stl" scale="1.4 1.4 1.4"/>
      </geometry>
    </visual>
    <collision>
      <origin rpy="0 0 0" xyz="0 0 0"/>
      <geometry>
        <mesh filename="package://wam_model/models/sw_meshes/tennis_robot - Wheelchair Wheel.stl" scale="1.4 1.4 1.4"/>
      </geometry>
    </collision>
  </link>

    <joint name="wheel_joint_2" type="revolute">
        <parent link="frame"/>
        <child link="wheel_2"/>
        <origin rpy="-1.06465 0 0" xyz="0.000  0.45  -0.20"/>
        <axis xyz="0 0 1"/>
        <limit effort="53"  velocity="3"/>
        <dynamics damping="0.9" friction="0"/>
    </joint>

    <link name="wheel_2">
    <inertial>
    <mass value="0.5"/>
    <inertia ixx=".13488033" ixy="-0.00213041" ixz="-0.00012485" iyy="0.11328369" iyz="0.00068555" izz="0.09046330"/>
    </inertial>
      <visual>
      <origin rpy="0 0 0" xyz="0 0 0"/>
      <material name="WAMGrey">
        <color rgba="0.7 0.7 0.7 1.0"/>
      </material>
      <geometry>
        <mesh filename="package://wam_model/models/sw_meshes/tennis_robot - Wheelchair Wheel.stl" scale="1.4 1.4 1.4"/>
      </geometry>
    </visual>
    <collision>
      <origin rpy="0 0 0" xyz="0 0 0"/>
      <geometry>
        <mesh filename="package://wam_model/models/sw_meshes/tennis_robot - Wheelchair Wheel.stl" scale="1.4 1.4 1.4"/>
      </geometry>
    </collision> 
  </link>

    <transmission name="wheel_1_trans">
        <type>transmission_interface/SimpleTransmission</type>
        <joint name="wheel_joint_1">
            <hardwareInterface>hardware_interface/PositionJointInterface</hardwareInterface>
        </joint>

        <actuator name="wheel_1_motor">
            <hardwareInterface>hardware_interface/PositionJointInterface</hardwareInterface>
            <mechanicalReduction>40</mechanicalReduction>
        </actuator>
    </transmission>

    <transmission name="wheel_2_trans">
        <type>transmission_interface/SimpleTransmission</type>
        <joint name="wheel_joint_2">
            <hardwareInterface>hardware_interface/PositionJointInterface</hardwareInterface>
        </joint>

        <actuator name="wheel_2_motor">
            <hardwareInterface>hardware_interface/PositionJointInterface</hardwareInterface>
            <mechanicalReduction>40</mechanicalReduction>
        </actuator>
    </transmission>



    <joint name="support_wheel_joint_1" type="revolute">
        <parent link="bracket_1"/>
        <child link="sw_1"/>
        <origin rpy="0 0 1.57" xyz="0 0 -0.037"/>
        <axis xyz="0 1 0"/>
        <limit effort="53"  velocity="3"/>
        <dynamics damping="0.9" friction="0"/>
    </joint>

    <link name="sw_1">
        <inertial>
    <mass value="0.05"/>
    <inertia ixx="0.01" ixy="0" ixz="0" iyy="0.01" iyz="0" izz="0.01"/>
    </inertial>
      <visual>
      <origin rpy="0 0 0" xyz="0 0 0"/>
      <material name="WAMGrey">
        <color rgba="0.7 0.7 0.7 1.0"/>
      </material>
      <geometry>
        <mesh filename="package://wam_model/models/sw_meshes/tennis_robot - whlsmall.stl" scale="1.5 1.5 1.5"/>
      </geometry>
    </visual>
    <collision>
      <origin rpy="0 0 0" xyz="0 0 0"/>
      <geometry>
        <mesh filename="package://wam_model/models/sw_meshes/tennis_robot - whlsmall.stl" scale="1.5 1.5 1.5"/>
      </geometry>
    </collision>
  </link>



    <joint name="support_wheel_joint_2" type="revolute">
        <parent link="bracket_2"/>
        <child link="sw_2"/>
        <origin rpy="0 0 1.57" xyz="0 0 -0.037"/>
        <axis xyz="0 1 0"/>
        <limit effort="53"  velocity="3"/>
        <dynamics damping="0.9" friction="0"/>

    </joint>

    <link name="sw_2">
        <inertial>
    <mass value="0.05"/>
    <inertia ixx="0.01" ixy="0" ixz="0" iyy="0.01" iyz="0" izz="0.01"/>
    </inertial>
      <visual>
      <origin rpy="0 0 0" xyz="0 0 0"/>
      <material name="WAMGrey">
        <color rgba="0.7 0.7 0.7 1.0"/>
      </material>
      <geometry>
        <mesh filename="package://wam_model/models/sw_meshes/tennis_robot - whlsmall.stl" scale="1.5 1.5 1.5"/>
      </geometry>
    </visual>
    <collision>
      <origin rpy="0 0 0" xyz="0 0 0"/>
      <geometry>
        <mesh filename="package://wam_model/models/sw_meshes/tennis_robot - whlsmall.stl" scale="1.5 1.5 1.5"/>
      </geometry>
    </collision>
  </link>

    <joint name="support_wheel_joint_3" type="revolute">
        <parent link="bracket_3"/>
        <child link="sw_3"/>
        <origin rpy="0 0 1.57" xyz="0 0 -0.037"/>
        <axis xyz="0 1 0"/>
        <limit effort="53"  velocity="3"/>
        <dynamics damping="0.9" friction="0"/>

    </joint>

    <link name="sw_3">
    <inertial>
    <mass value="0.05"/>
    <inertia ixx="0.01" ixy="0" ixz="0" iyy="0.01" iyz="0" izz="0.01"/>
    </inertial>
      <visual>
      <origin rpy="0 0 0" xyz="0 0 0"/>
      <material name="WAMGrey">
        <color rgba="0.7 0.7 0.7 1.0"/>
      </material>
      <geometry>
        <mesh filename="package://wam_model/models/sw_meshes/tennis_robot - whlsmall.stl" scale="1.5 1.5 1.5"/>
      </geometry>
    </visual>
    <collision>
      <origin rpy="0 0 0" xyz="0 0 0"/>
      <geometry>
        <mesh filename="package://wam_model/models/sw_meshes/tennis_robot - whlsmall.stl" scale="1.5 1.5 1.5"/>
      </geometry>
    </collision>
  </link>

<!-- End -->

  <gazebo reference="wam/wheelchair_link">
    <turnGravityOff>0</turnGravityOff>
    <material>Gazebo/Grey</material>
  </gazebo>
  <joint name="lidar_mount_joint" type="fixed">
    <parent link="wam/wheelchair_link"/>
    <child link="lidar_mount_link"/>
    <origin rpy="0 0 0" xyz="0.19739 0 -0.10835"/>
  </joint>
  <link name="lidar_mount_link">
    <visual>
      <origin rpy="0 0 0" xyz="0 0 0"/>
      <material name="Black">
        <color rgba="0.0 0.0 0.0 1.0"/>
      </material>
      <geometry>
        <mesh filename="package://wam_model/models/sw_meshes/vlp16_mount.stl" scale="0.001 0.001 0.001"/>
      </geometry>
    </visual>
    <collision>
      <origin rpy="0 0 0" xyz="0 0 0"/>
      <geometry>
        <mesh filename="package://wam_model/models/sw_meshes/vlp16_mount.stl" scale="0.0009 0.0009 0.0009"/>
      </geometry>
    </collision>
  </link>
  <joint name="lidar_joint" type="fixed">
    <parent link="lidar_mount_link"/>
    <child link="lidar_link"/>
    <origin rpy="0 0 0" xyz="0 0 0"/>
  </joint>
  <link name="lidar_link">
    <visual>
      <material name="Blue">
        <color rgba="0.1725 0.1059 0.7019 1.0"/>
      </material>
      <origin rpy="0 0 0" xyz="0 0 0"/>
      <geometry>
        <mesh filename="package://wam_model/models/sw_meshes/vlp_16.stl" scale="0.001 0.001 0.001"/>
      </geometry>
    </visual>
    <collision>
      <origin rpy="0 0 0" xyz="0 0 0.001"/>
      <geometry>
        <mesh filename="package://wam_model/models/sw_meshes/vlp_16.stl" scale="0.0009 0.0009 0.0009"/>
      </geometry>
    </collision>
  </link>
  <material name="zed_mat">
    <color rgba="0.8 0.8 0.8 0.8"/>
  </material>
  <material name="zedm_mat">
    <color rgba="0 0 0 0.9"/>
  </material>
  <material name="zed2_mat">
    <color rgba="0.25 0.25 0.25 0.99"/>
  </material>
  <material name="zed2i_mat">
    <color rgba="0.25 0.25 0.25 0.99"/>
  </material>
  <!-- Camera mounting point (the threaded screw hole in the bottom) -->
  <link name="camera_0_base_link"/>
  <joint name="camera_0_base_joint" type="fixed">
    <parent link="wam/wheelchair_link"/>
    <child link="camera_0_base_link"/>
    <origin rpy="0 0 0" xyz="0.3333589 0 0"/>
  </joint>
  <!-- Camera Center -->
  <link name="camera_0_camera_center">
    <visual>
      <origin rpy="0 0 0" xyz="0.0 0 0"/>
      <geometry>
        <mesh filename="package://ball_calibration/models/models/zed2.stl" scale="1 1 1"/>
      </geometry>
      <material name="zed2_mat"/>
    </visual>
    <collision>
      <geometry>
        <mesh filename="package://ball_calibration/models/models/zed2.stl" scale="0.92 0.92 0.92"/>
      </geometry>
    </collision>
  </link>
  <joint name="camera_0_camera_center_joint" type="fixed">
    <parent link="camera_0_base_link"/>
    <child link="camera_0_camera_center"/>
    <origin rpy="0 0.05 0" xyz="0 0 0.015"/>
  </joint>
  <!-- Left Camera -->
  <link name="camera_0_left_camera_frame"/>
  <joint name="camera_0_left_camera_joint" type="fixed">
    <parent link="camera_0_camera_center"/>
    <child link="camera_0_left_camera_frame"/>
    <origin rpy="0 0 0" xyz="0 0.06 0"/>
  </joint>
  <link name="camera_0_left_camera_optical_frame"/>
  <joint name="camera_0_left_camera_optical_joint" type="fixed">
    <origin rpy="-1.5707963267948966 0.0 -1.5707963267948966" xyz="-0.01 0 0"/>
    <parent link="camera_0_left_camera_frame"/>
    <child link="camera_0_left_camera_optical_frame"/>
  </joint>
  <!-- Right Camera -->
  <link name="camera_0_right_camera_frame"/>
  <joint name="camera_0_right_camera_joint" type="fixed">
    <parent link="camera_0_camera_center"/>
    <child link="camera_0_right_camera_frame"/>
    <origin rpy="0 0 0" xyz="0 -0.06 0"/>
  </joint>
  <link name="camera_0_right_camera_optical_frame"/>
  <joint name="camera_0_right_camera_optical_joint" type="fixed">
    <origin rpy="-1.5707963267948966 0.0 -1.5707963267948966" xyz="-0.01 0 0"/>
    <parent link="camera_0_right_camera_frame"/>
    <child link="camera_0_right_camera_optical_frame"/>
  </joint>
  <!-- ZED2 Sensors -->
  <link name="camera_0_imu_link"/>
  <joint name="camera_0_imu_link_joint" type="fixed">
    <parent link="camera_0_left_camera_frame"/>
    <child link="camera_0_imu_link"/>
    <origin rpy="0.00138 -0.00116 -0.00176" xyz="-0.002 -0.023 -0.002"/>
  </joint>
  <link name="camera_0_mag_link"/>
  <joint name="camera_0_mag_joint" type="fixed">
    <parent link="camera_0_camera_center"/>
    <child link="camera_0_mag_link"/>
    <origin rpy="0 0 0" xyz="0 0 0"/>
  </joint>
  <link name="camera_0_baro_link"/>
  <joint name="camera_0_baro_joint" type="fixed">
    <parent link="camera_0_camera_center"/>
    <child link="camera_0_baro_link"/>
    <origin rpy="0 0 0" xyz="0 0 0"/>
  </joint>
  <link name="camera_0_temp_left_link"/>
  <joint name="camera_0_temp_left_joint" type="fixed">
    <parent link="camera_0_left_camera_frame"/>
    <child link="camera_0_temp_left_link"/>
    <origin rpy="0 0 0" xyz="0 0 0"/>
  </joint>
  <link name="camera_0_temp_right_link"/>
  <joint name="camera_0_temp_right_joint" type="fixed">
    <parent link="camera_0_right_camera_frame"/>
    <child link="camera_0_temp_right_link"/>
    <origin rpy="0 0 0" xyz="0 0 0"/>
  </joint>
  <!-- <xacro:wheelchair_rollers prefix="${prefix}"/> -->
  <!-- <xacro:wheelchair_wheels prefix="${prefix}"/> -->
</robot>
